<?xml version="1.0" ?><robot name="Unity Export v1"><attributes/><joint name="unityjoint_0" type="continuous"><parent link="unitycomp_0"/><child link="unitycomp_6"/><axis xyz="-0.0 0.447213595499958 0.894427190999916"/><origin xyz="11.1089139840713 -15.107831805972632 12.212485706735311"/></joint><joint name="unityjoint_1" type="continuous"><parent link="unitycomp_0"/><child link="unitycomp_7"/><axis xyz="0.0 -0.447213595499958 -0.894427190999916"/><origin xyz="-11.7510860159287 -15.107831805972632 12.212485706735311"/></joint><joint name="unityjoint_2" type="continuous"><parent link="unitycomp_0"/><child link="unitycomp_1"/><axis xyz="-1.0 -0.0 -0.0"/><origin xyz="-12.3210860159287 21.753627807318 -0.04770799760279987"/></joint><joint name="unityjoint_3" type="continuous"><parent link="unitycomp_0"/><child link="wheel_5"/><axis xyz="-1.0 -0.0 -0.0"/><origin xyz="-21.383585622541503 16.953627807325596 -0.04770799760409972"/><wheel type="mecanum"/></joint><joint name="unityjoint_4" type="continuous"><parent link="unitycomp_0"/><child link="wheel_2"/><axis xyz="-1.0 -0.0 -0.0"/><origin xyz="-21.383585622541403 -16.6463721926744 -0.047707997604001684"/><wheel type="mecanum"/></joint><joint name="unityjoint_5" type="continuous"><parent link="unitycomp_0"/><child link="wheel_4"/><axis xyz="1.0 -0.0 -0.0"/><origin xyz="20.741414377462405 16.953627807317996 -0.047707997603001595"/><wheel type="mecanum"/></joint><joint name="unityjoint_6" type="continuous"><parent link="unitycomp_0"/><child link="wheel_3"/><axis xyz="1.0 -0.0 -0.0"/><origin xyz="20.741414377462505 -16.646372192682 -0.04770799760309963"/><wheel type="mecanum"/></joint><motor name="frontLeft"><powered joints="unityjoint_6"/><attributes gearRatio="1" maxRPM="340" encoderTicksPerRev="560"/></motor><motor name="frontRight"><powered joints="unityjoint_4"/><attributes gearRatio="1" maxRPM="340" encoderTicksPerRev="560"/></motor><motor name="backLeft"><powered joints="unityjoint_5"/><attributes gearRatio="1" maxRPM="340" encoderTicksPerRev="560"/></motor><motor name="backRight"><powered joints="unityjoint_3"/><attributes gearRatio="1" maxRPM="340" encoderTicksPerRev="560"/></motor><motor name="ringCollection"><powered joints="unityjoint_2"/><attributes gearRatio="1" maxRPM="340" encoderTicksPerRev="560"/></motor><motor name="ringLoader"><attributes gearRatio="1" maxRPM="340" encoderTicksPerRev="560"/></motor><motor name="ringShooter"><powered joints="unityjoint_0 unityjoint_1"/><attributes gearRatio="1" maxRPM="680" encoderTicksPerRev="560"/></motor><motor name="wobbleActuator"><attributes gearRatio="1" maxRPM="340" encoderTicksPerRev="560"/></motor></robot>