<?xml version="1.0" ?><robot name="Unity Export v1"><attributes/><joint name="unityjoint_0" type="continuous"><parent link="unitycomp_1"/><child link="wheel_2"/><axis xyz="-1.0 -1.4802973661668762e-15 -3.7007434154171906e-16"/><origin xyz="12.252356916063679 12.38914748426112 -1.4929105275369805"/><wheel type="mecanum"/></joint><joint name="unityjoint_1" type="continuous"><parent link="unitycomp_1"/><child link="unitycomp_3"/><axis xyz="-1.0 0.0 -3.7007434154171906e-16"/><origin xyz="-4.547643083936244 -21.21085251573896 -1.492910527536909"/></joint><joint name="unityjoint_2" type="continuous"><parent link="unitycomp_1"/><child link="wheel_4"/><axis xyz="-1.0 0.0 -3.70074341541718e-16"/><origin xyz="-21.347643083936184 -21.210852515738996 -1.492910527536917"/><wheel type="mecanum"/></joint><joint name="unityjoint_3" type="continuous"><parent link="unitycomp_1"/><child link="wheel_5"/><axis xyz="-1.0 0.0 -3.7007434154171906e-16"/><origin xyz="12.252356916063693 -21.210852515738953 -1.4929105275369063"/><wheel type="mecanum"/></joint><joint name="unityjoint_4" type="continuous"><parent link="unitycomp_1"/><child link="wheel_6"/><axis xyz="1.0 1.480297366166872e-15 3.70074341541718e-16"/><origin xyz="-21.3476430839362 12.389147484261084 -1.4929105275369912"/><wheel type="mecanum"/></joint><motor name="frontLeft"><powered joints="unityjoint_2"/><attributes gearRatio="1" maxRPM="340" encoderTicksPerRev="560"/></motor><motor name="frontRight"><powered joints="unityjoint_3"/><attributes gearRatio="1" maxRPM="340" encoderTicksPerRev="560"/></motor><motor name="backLeft"><powered joints="unityjoint_4"/><attributes gearRatio="1" maxRPM="340" encoderTicksPerRev="560"/></motor><motor name="backRight"><powered joints="unityjoint_0"/><attributes gearRatio="1" maxRPM="340" encoderTicksPerRev="560"/></motor></robot>